Workbook

Sheet Изчисления
A1: ІІ. Изчисление и топлотехническа оценка на сградата
A2: 1.Геометрични характеристики на сградата
O3: дълж на топлинен мост на стени
A4: Описание на геометрията на сградата
C5: Af | E5: h | F5: V | G5: P | H5: Aок | I5: Аерк | J5: Lерк | K5: n
C6: m2 | E6: m | F6: m3 | G6: m | H6: m2 | I6: m2 | J6: m | K6: бр
A7: I етаж | F7: =E7*C7 -> 0 | G7: =L31 -> 0 | H7: =G7*E7 -> 0 | O7: =K7*E7 -> 0
A8: ІІ етаж | F8: =E8*C8 -> 0 | G8: =L32 -> 0 | H8: =G8*E8 -> 0 | O8: =K8*E8 -> 0
A9: ІІІ етаж | F9: =E9*C9 -> 0 | G9: =L33 -> 0 | H9: =G9*E9 -> 0 | O9: =K9*E9 -> 0
A10: ІV етаж | F10: =E10*C10 -> 0 | G10: =L34 -> 0 | H10: =G10*E10 -> 0 | O10: =K10*E10 -> 0
A11: V етаж | F11: =E11*C11 -> 0 | G11: =L35 -> 0 | H11: =G11*E11 -> 0 | O11: =K11*E11 -> 0
A12: VІ етаж | F12: =E12*C12 -> 0 | G12: =L36 -> 0 | H12: =G12*E12 -> 0 | O12: =K12*E12 -> 0
A13: VІІ етаж | F13: =E13*C13 -> 0 | G13: =L37 -> 0 | H13: =G13*E13 -> 0 | O13: =K13*E13 -> 0
A14: VІІІ етаж | F14: =E14*C14 -> 0 | G14: =L38 -> 0 | H14: =G14*E14 -> 0 | O14: =K14*E14 -> 0
F15: =E15*C15 -> 0 | G15: =L39 -> 0 | H15: =G15*E15 -> 0 | O15: =K15*E15 -> 0
F16: =E16*C16 -> 0 | G16: =L40 -> 0 | H16: =G16*E16 -> 0 | O16: =K16*E16 -> 0
F17: =E17*C17 -> 0 | G17: =L41 -> 0 | H17: =G17*E17 -> 0 | O17: =K17*E17 -> 0
F18: =E18*C18 -> 0 | G18: =L42 -> 0 | H18: =G18*E18 -> 0
F19: =E19*C19 -> 0 | G19: =L43 -> 0 | H19: =G19*E19 -> 0
F20: =E20*C20 -> 0 | G20: =L44 -> 0 | H20: =G20*E20 -> 0
F21: =E21*C21 -> 0 | G21: =L45 -> 0 | H21: =G21*E21 -> 0
F22: =E22*C22 -> 0 | G22: =L46 -> 0 | H22: =G22*E22 -> 0
F23: =E23*C23 -> 0 | G23: =L47 -> 0 | H23: =G23*E23 -> 0
F24: =E24*C24 -> 0 | G24: =L48 -> 0 | H24: =G24*E24 -> 0 | O24: =K24*E24 -> 0
A25: Общо | C25: =SUM(C7:C24) -> 0 | F25: =SUM(F7:F24) -> 0 | G25: =SUM(G7:G24) -> 0 | H25: =SUM(H7:H24) -> 0 | I25: =SUM(I7:I24) -> 0 | J25: =SUM(J7:J24) -> 0 | O25: =SUM(O7:P24) -> 0
A27: Описание на стените по фасади (включително прозорци и врати)
C28: h | D28: Дължина на фасадите | L28: Периметър
D29: С | E29: СИ | F29: И | G29: ЮИ | H29: Ю | I29: ЮЗ | J29: З | K29: СЗ | N29: С | O29: СИ | P29: И | Q29: ЮИ | R29: Ю | S29: ЮЗ | T29: З | U29: СЗ
C30: m | D30: m | E30: m | F30: m | G30: m | H30: m | I30: m | J30: m | K30: m | L30: m | N30: m2 | O30: m2 | P30: m2 | Q30: m2 | R30: m2 | S30: m2 | T30: m2 | U30: m2
A31: =IF(A7="","",A7) -> I етаж | C31: =E7 -> 0 | L31: =SUM(D31:K31) -> 0 | N31: =D31*$C31 -> 0 | O31: =E31*$C31 -> 0 | P31: =F31*$C31 -> 0 | Q31: =G31*$C31 -> 0 | R31: =H31*$C31 -> 0 | S31: =I31*$C31 -> 0 | T31: =J31*$C31 -> 0 | U31: =K31*$C31 -> 0
A32: =IF(A8="","",A8) -> ІІ етаж | C32: =E8 -> 0 | L32: =SUM(D32:K32) -> 0 | N32: =D32*$C32 -> 0 | O32: =E32*$C32 -> 0 | P32: =F32*$C32 -> 0 | Q32: =G32*$C32 -> 0 | R32: =H32*$C32 -> 0 | S32: =I32*$C32 -> 0 | T32: =J32*$C32 -> 0 | U32: =K32*$C32 -> 0
A33: =IF(A9="","",A9) -> ІІІ етаж | C33: =E9 -> 0 | L33: =SUM(D33:K33) -> 0 | N33: =D33*$C33 -> 0 | O33: =E33*$C33 -> 0 | P33: =F33*$C33 -> 0 | Q33: =G33*$C33 -> 0 | R33: =H33*$C33 -> 0 | S33: =I33*$C33 -> 0 | T33: =J33*$C33 -> 0 | U33: =K33*$C33 -> 0
A34: =IF(A10="","",A10) -> ІV етаж | C34: =E10 -> 0 | L34: =SUM(D34:K34) -> 0 | N34: =D34*$C34 -> 0 | O34: =E34*$C34 -> 0 | P34: =F34*$C34 -> 0 | Q34: =G34*$C34 -> 0 | R34: =H34*$C34 -> 0 | S34: =I34*$C34 -> 0 | T34: =J34*$C34 -> 0 | U34: =K34*$C34 -> 0
A35: =IF(A11="","",A11) -> V етаж | C35: =E11 -> 0 | L35: =SUM(D35:K35) -> 0 | N35: =D35*$C35 -> 0 | O35: =E35*$C35 -> 0 | P35: =F35*$C35 -> 0 | Q35: =G35*$C35 -> 0 | R35: =H35*$C35 -> 0 | S35: =I35*$C35 -> 0 | T35: =J35*$C35 -> 0 | U35: =K35*$C35 -> 0
A36: =IF(A12="","",A12) -> VІ етаж | C36: =E12 -> 0 | L36: =SUM(D36:K36) -> 0 | N36: =D36*$C36 -> 0 | O36: =E36*$C36 -> 0 | P36: =F36*$C36 -> 0 | Q36: =G36*$C36 -> 0 | R36: =H36*$C36 -> 0 | S36: =I36*$C36 -> 0 | T36: =J36*$C36 -> 0 | U36: =K36*$C36 -> 0
A37: =IF(A13="","",A13) -> VІІ етаж | C37: =E13 -> 0 | L37: =SUM(D37:K37) -> 0 | N37: =D37*$C37 -> 0 | O37: =E37*$C37 -> 0 | P37: =F37*$C37 -> 0 | Q37: =G37*$C37 -> 0 | R37: =H37*$C37 -> 0 | S37: =I37*$C37 -> 0 | T37: =J37*$C37 -> 0 | U37: =K37*$C37 -> 0
A38: =IF(A14="","",A14) -> VІІІ етаж | C38: =E14 -> 0 | L38: =SUM(D38:K38) -> 0 | N38: =D38*$C38 -> 0 | O38: =E38*$C38 -> 0 | P38: =F38*$C38 -> 0 | Q38: =G38*$C38 -> 0 | R38: =H38*$C38 -> 0 | S38: =I38*$C38 -> 0 | T38: =J38*$C38 -> 0 | U38: =K38*$C38 -> 0
A39: =IF(A15="","",A15) | C39: =E15 -> 0 | L39: =SUM(D39:K39) -> 0 | N39: =D39*$C39 -> 0 | O39: =E39*$C39 -> 0 | P39: =F39*$C39 -> 0 | Q39: =G39*$C39 -> 0 | R39: =H39*$C39 -> 0 | S39: =I39*$C39 -> 0 | T39: =J39*$C39 -> 0 | U39: =K39*$C39 -> 0
A40: =IF(A16="","",A16) | C40: =E16 -> 0 | L40: =SUM(D40:K40) -> 0 | N40: =D40*$C40 -> 0 | O40: =E40*$C40 -> 0 | P40: =F40*$C40 -> 0 | Q40: =G40*$C40 -> 0 | R40: =H40*$C40 -> 0 | S40: =I40*$C40 -> 0 | T40: =J40*$C40 -> 0 | U40: =K40*$C40 -> 0
A41: =IF(A17="","",A17) | C41: =E17 -> 0 | L41: =SUM(D41:K41) -> 0 | N41: =D41*$C41 -> 0 | O41: =E41*$C41 -> 0 | P41: =F41*$C41 -> 0 | Q41: =G41*$C41 -> 0 | R41: =H41*$C41 -> 0 | S41: =I41*$C41 -> 0 | T41: =J41*$C41 -> 0 | U41: =K41*$C41 -> 0
...

Sheet Стойности
A2: Типове сгради: | D2: =Изчисления!K192 -> 2 | F2: =INDIRECT("A"&3+D2) -> Еднофамилна жилищна сграда
A4: Многофамилна жилищна сграда в това число и общежитие
A5: Еднофамилна жилищна сграда
A6: Административна сграда
A7: Училище
A8: Университет
A9: Детска градина и детска ясла
A10: Сграда за здравеопазване
A11: Хотели и ресторанти
A12: Сграда за търговия
A13: Сграда за спорт
A14: Сграда за култура и изкуство
A21: Използван клас на енергопотребление | F21: Почивни дни
A22: Клас | B22: EPmin | C22: EPmax | F22: Януари | G22: Февруари | H22: Март | I22: Април | J22: Май | K22: Юни | L22: Юли | M22: Август | N22: Септември | O22: Октомври | P22: Ноември | Q22: Декември
A23: A | B23: не се дефинира | C23: =INDIRECT("C"&D2*9+23) -> 83 | F23: =INDIRECT("F"&D2*9+23) -> 0 | G23: =INDIRECT("g"&D2*9+23) -> 0 | H23: =INDIRECT("h"&D2*9+23) -> 0 | I23: =INDIRECT("i"&D2*9+23) -> 0 | J23: =INDIRECT("j"&D2*9+23) -> 0 | K23: =INDIRECT("k"&D2*9+23) -> 0 | L23: =INDIRECT("l"&D2*9+23) -> 0 | M23: =INDIRECT("m"&D2*9+23) -> 0 | N23: =INDIRECT("n"&D2*9+23) -> 0 | O23: =INDIRECT("o"&D2*9+23) -> 0 | P23: =INDIRECT("p"&D2*9+23) -> 0 | Q23: =INDIRECT("q"&D2*9+23) -> 0
A24: B | B24: =C23 -> 83 | C24: =INDIRECT("C"&D2*9+24) -> 166
A25: C | B25: =C24 -> 166 | C25: =INDIRECT("C"&D2*9+25) -> 203 | F25: =INDIRECT("F"&D2*9+25) -> БГВ= | G25: =INDIRECT("g"&D2*9+25) -> 80 | H25: =INDIRECT("h"&D2*9+25) -> л/ден
A26: D | B26: =C25 -> 203 | C26: =INDIRECT("C"&D2*9+26) -> 240
A27: E | B27: =C26 -> 240 | C27: =INDIRECT("C"&D2*9+27) -> 300
A28: F | B28: =C27 -> 300 | C28: =INDIRECT("C"&D2*9+28) -> 360
A29: G | B29: =C28 -> 360 | C29: не се дефинира
A30: Жилищни сгради - многофамилни | F30: Почивни дни
A31: Клас | B31: EPmin | C31: EPmax | F31: Януари | G31: Февруари | H31: Март | I31: Април | J31: Май | K31: Юни | L31: Юли | M31: Август | N31: Септември | O31: Октомври | P31: Ноември | Q31: Декември
A32: A | C32: 90 | F32: 0 | G32: 0 | H32: 0 | I32: 0 | J32: 0 | K32: 0 | L32: 0 | M32: 0 | N32: 0 | O32: 0 | P32: 0 | Q32: 0
A33: B | B33: =C32 -> 90 | C33: 180
A34: C | B34: =C33 -> 180 | C34: 235 | F34: БГВ= | G34: 80 | H34: л/ден
A35: D | B35: =C34 -> 235 | C35: 290
A36: E | B36: =C35 -> 290 | C36: 363
A37: F | B37: =C36 -> 363 | C37: 435
A38: G | B38: =C37 -> 435
A39: Жилищни сгради - еднофамилни | F39: Почивни дни
A40: Клас | B40: EPmin | C40: EPmax | F40: Януари | G40: Февруари | H40: Март | I40: Април | J40: Май | K40: Юни | L40: Юли | M40: Август | N40: Септември | O40: Октомври | P40: Ноември | Q40: Декември
A41: A | C41: 83 | F41: 0 | G41: 0 | H41: 0 | I41: 0 | J41: 0 | K41: 0 | L41: 0 | M41: 0 | N41: 0 | O41: 0 | P41: 0 | Q41: 0
A42: B | B42: =C41 -> 83 | C42: 166
A43: C | B43: =C42 -> 166 | C43: 203 | F43: БГВ= | G43: 80 | H43: л/ден
A44: D | B44: =C43 -> 203 | C44: 240
A45: E | B45: =C44 -> 240 | C45: 300
A46: F | B46: =C45 -> 300 | C46: 360
A47: G | B47: =C46 -> 360
A48: Сгради за административно обслужване | F48: Почивни дни
...

Sheet Климатични зони
A1: Данни които се използват в сметките
B3: Час | C3: - | D3: 0 | E3: 1 | F3: 2 | G3: 3 | H3: 4 | I3: 5 | J3: 6 | K3: 7 | L3: 8 | M3: 9 | N3: 10 | O3: 11 | P3: 12 | Q3: 13 | R3: 14 | S3: 15 | T3: 16 | U3: 17 | V3: 18 | W3: 19 | X3: 20 | Y3: 21 | Z3: 22 | AA3: 23 | AB3: Зимен период
A4: Януари | B4: θе | C4: C | D4: =IF(Изчисления!$K$196=1,$D$21,INDIRECT("D"&Изчисления!$K$188*30+ROW()-1)) -> 2.2 | E4: =IF(Изчисления!$K$196=1,$D$21,INDIRECT("D"&Изчисления!$K$188*30+ROW()-1)) -> 2.2 | F4: =IF(Изчисления!$K$196=1,$D$21,INDIRECT("D"&Изчисления!$K$188*30+ROW()-1)) -> 2.2 | G4: =IF(Изчисления!$K$196=1,$D$21,INDIRECT("D"&Изчисления!$K$188*30+ROW()-1)) -> 2.2 | H4: =IF(Изчисления!$K$196=1,$D$21,INDIRECT("D"&Изчисления!$K$188*30+ROW()-1)) -> 2.2 | I4: =IF(Изчисления!$K$196=1,$D$21,INDIRECT("D"&Изчисления!$K$188*30+ROW()-1)) -> 2.2 | J4: =IF(Изчисления!$K$196=1,$D$21,INDIRECT("D"&Изчисления!$K$188*30+ROW()-1)) -> 2.2 | K4: =IF(Изчисления!$K$196=1,$D$21,INDIRECT("D"&Изчисления!$K$188*30+ROW()-1)) -> 2.2 | ... AA4: =IF(Изчисления!$K$196=1,$D$21,INDIRECT("D"&Изчисления!$K$188*30+ROW()-1)) -> 2.2 | AB4: Isol, с | AC4: W/m2 | AD4: =INDIRECT("ad"&Изчисления!$K$188*30+ROW()-1) -> 23.9 | AE4: =INDIRECT("ae"&Изчисления!$K$188*30+ROW()-1) -> 36.5 | AF4: =INDIRECT("af"&Изчисления!$K$188*30+ROW()-1) -> 49.6 | AG4: =INDIRECT("ag"&Изчисления!$K$188*30+ROW()-1) -> 65.6 | AH4: =INDIRECT("ah"&Изчисления!$K$188*30+ROW()-1) -> 41.8 | AI4: =INDIRECT("ai"&Изчисления!$K$188*30+ROW()-1) -> 27.2 | AJ4: =INDIRECT("aj"&Изчисления!$K$188*30+ROW()-1) -> 21
A5: Февруари | B5: θе | C5: C | D5: =IF(Изчисления!$K$196=1,$E$21,INDIRECT("D"&Изчисления!$K$188*30+ROW()-1)) -> 2.9 | E5: =IF(Изчисления!$K$196=1,$E$21,INDIRECT("D"&Изчисления!$K$188*30+ROW()-1)) -> 2.9 | F5: =IF(Изчисления!$K$196=1,$E$21,INDIRECT("D"&Изчисления!$K$188*30+ROW()-1)) -> 2.9 | G5: =IF(Изчисления!$K$196=1,$E$21,INDIRECT("D"&Изчисления!$K$188*30+ROW()-1)) -> 2.9 | H5: =IF(Изчисления!$K$196=1,$E$21,INDIRECT("D"&Изчисления!$K$188*30+ROW()-1)) -> 2.9 | I5: =IF(Изчисления!$K$196=1,$E$21,INDIRECT("D"&Изчисления!$K$188*30+ROW()-1)) -> 2.9 | J5: =IF(Изчисления!$K$196=1,$E$21,INDIRECT("D"&Изчисления!$K$188*30+ROW()-1)) -> 2.9 | K5: =IF(Изчисления!$K$196=1,$E$21,INDIRECT("D"&Изчисления!$K$188*30+ROW()-1)) -> 2.9 | ... AA5: =IF(Изчисления!$K$196=1,$E$21,INDIRECT("D"&Изчисления!$K$188*30+ROW()-1)) -> 2.9 | AB5: Isol, и | AC5: W/m2 | AD5: =INDIRECT("ad"&Изчисления!$K$188*30+ROW()-1) -> 43 | AE5: =INDIRECT("ae"&Изчисления!$K$188*30+ROW()-1) -> 64.9 | AF5: =INDIRECT("af"&Изчисления!$K$188*30+ROW()-1) -> 74.9 | AG5: =INDIRECT("ag"&Изчисления!$K$188*30+ROW()-1) -> 92.4 | AH5: =INDIRECT("ah"&Изчисления!$K$188*30+ROW()-1) -> 75.1 | AI5: =INDIRECT("ai"&Изчисления!$K$188*30+ROW()-1) -> 49.6 | AJ5: =INDIRECT("aj"&Изчисления!$K$188*30+ROW()-1) -> 38.3
A6: Март | B6: θе | C6: C | D6: =IF(Изчисления!$K$196=1,$F$21,INDIRECT("D"&Изчисления!$K$188*30+ROW()-1)) -> 5.7 | E6: =IF(Изчисления!$K$196=1,$F$21,INDIRECT("D"&Изчисления!$K$188*30+ROW()-1)) -> 5.7 | F6: =IF(Изчисления!$K$196=1,$F$21,INDIRECT("D"&Изчисления!$K$188*30+ROW()-1)) -> 5.7 | G6: =IF(Изчисления!$K$196=1,$F$21,INDIRECT("D"&Изчисления!$K$188*30+ROW()-1)) -> 5.7 | H6: =IF(Изчисления!$K$196=1,$F$21,INDIRECT("D"&Изчисления!$K$188*30+ROW()-1)) -> 5.7 | I6: =IF(Изчисления!$K$196=1,$F$21,INDIRECT("D"&Изчисления!$K$188*30+ROW()-1)) -> 5.7 | J6: =IF(Изчисления!$K$196=1,$F$21,INDIRECT("D"&Изчисления!$K$188*30+ROW()-1)) -> 5.7 | K6: =IF(Изчисления!$K$196=1,$F$21,INDIRECT("D"&Изчисления!$K$188*30+ROW()-1)) -> 5.7 | ... AA6: =IF(Изчисления!$K$196=1,$F$21,INDIRECT("D"&Изчисления!$K$188*30+ROW()-1)) -> 5.7 | AB6: Isol, ю | AC6: W/m2 | AD6: =INDIRECT("ad"&Изчисления!$K$188*30+ROW()-1) -> 77.3 | AE6: =INDIRECT("ae"&Изчисления!$K$188*30+ROW()-1) -> 105.8 | AF6: =INDIRECT("af"&Изчисления!$K$188*30+ROW()-1) -> 97.1 | AG6: =INDIRECT("ag"&Изчисления!$K$188*30+ROW()-1) -> 91.5 | AH6: =INDIRECT("ah"&Изчисления!$K$188*30+ROW()-1) -> 117.4 | AI6: =INDIRECT("ai"&Изчисления!$K$188*30+ROW()-1) -> 87.7 | AJ6: =INDIRECT("aj"&Изчисления!$K$188*30+ROW()-1) -> 70.8
A7: Април | B7: θе | C7: C | D7: =IF(Изчисления!$K$196=1,$G$21,INDIRECT("D"&Изчисления!$K$188*30+ROW()-1)) -> 10.9 | E7: =IF(Изчисления!$K$196=1,$G$21,INDIRECT("D"&Изчисления!$K$188*30+ROW()-1)) -> 10.9 | F7: =IF(Изчисления!$K$196=1,$G$21,INDIRECT("D"&Изчисления!$K$188*30+ROW()-1)) -> 10.9 | G7: =IF(Изчисления!$K$196=1,$G$21,INDIRECT("D"&Изчисления!$K$188*30+ROW()-1)) -> 10.9 | H7: =IF(Изчисления!$K$196=1,$G$21,INDIRECT("D"&Изчисления!$K$188*30+ROW()-1)) -> 10.9 | I7: =IF(Изчисления!$K$196=1,$G$21,INDIRECT("D"&Изчисления!$K$188*30+ROW()-1)) -> 10.9 | J7: =IF(Изчисления!$K$196=1,$G$21,INDIRECT("D"&Изчисления!$K$188*30+ROW()-1)) -> 10.9 | K7: =IF(Изчисления!$K$196=1,$G$21,INDIRECT("D"&Изчисления!$K$188*30+ROW()-1)) -> 10.9 | ... AA7: =IF(Изчисления!$K$196=1,$G$21,INDIRECT("D"&Изчисления!$K$188*30+ROW()-1)) -> 10.9 | AB7: Isol, з | AC7: W/m2 | AD7: =INDIRECT("ad"&Изчисления!$K$188*30+ROW()-1) -> 43 | AE7: =INDIRECT("ae"&Изчисления!$K$188*30+ROW()-1) -> 64.9 | AF7: =INDIRECT("af"&Изчисления!$K$188*30+ROW()-1) -> 74.9 | AG7: =INDIRECT("ag"&Изчисления!$K$188*30+ROW()-1) -> 92.4 | AH7: =INDIRECT("ah"&Изчисления!$K$188*30+ROW()-1) -> 75.1 | AI7: =INDIRECT("ai"&Изчисления!$K$188*30+ROW()-1) -> 49.6 | AJ7: =INDIRECT("aj"&Изчисления!$K$188*30+ROW()-1) -> 38.3
A8: Май | B8: θе | C8: C | D8: =INDIRECT("D"&Изчисления!$K$188*30+ROW()-1) -> 13.3 | E8: =INDIRECT("E"&Изчисления!$K$188*30+ROW()-1) -> 13.1 | F8: =INDIRECT("f"&Изчисления!$K$188*30+ROW()-1) -> 12.9 | G8: =INDIRECT("g"&Изчисления!$K$188*30+ROW()-1) -> 12.7 | H8: =INDIRECT("h"&Изчисления!$K$188*30+ROW()-1) -> 12.5 | I8: =INDIRECT("i"&Изчисления!$K$188*30+ROW()-1) -> 13.4 | J8: =INDIRECT("j"&Изчисления!$K$188*30+ROW()-1) -> 14.3 | K8: =INDIRECT("k"&Изчисления!$K$188*30+ROW()-1) -> 15.2 | L8: =INDIRECT("l"&Изчисления!$K$188*30+ROW()-1) -> 16.1 | M8: =INDIRECT("m"&Изчисления!$K$188*30+ROW()-1) -> 17.2 | N8: =INDIRECT("n"&Изчисления!$K$188*30+ROW()-1) -> 18.2 | O8: =INDIRECT("o"&Изчисления!$K$188*30+ROW()-1) -> 18.1 | P8: =INDIRECT("p"&Изчисления!$K$188*30+ROW()-1) -> 18.1 | Q8: =INDIRECT("q"&Изчисления!$K$188*30+ROW()-1) -> 18.1 | R8: =INDIRECT("r"&Изчисления!$K$188*30+ROW()-1) -> 17.8 | S8: =INDIRECT("s"&Изчисления!$K$188*30+ROW()-1) -> 17.5 | T8: =INDIRECT("t"&Изчисления!$K$188*30+ROW()-1) -> 17.2 | U8: =INDIRECT("u"&Изчисления!$K$188*30+ROW()-1) -> 16.6 | V8: =INDIRECT("v"&Изчисления!$K$188*30+ROW()-1) -> 15.9 | W8: =INDIRECT("w"&Изчисления!$K$188*30+ROW()-1) -> 15.3 | X8: =INDIRECT("x"&Изчисления!$K$188*30+ROW()-1) -> 14.8 | Y8: =INDIRECT("y"&Изчисления!$K$188*30+ROW()-1) -> 14.3 | Z8: =INDIRECT("z"&Изчисления!$K$188*30+ROW()-1) -> 13.9 | AA8: =INDIRECT("aa"&Изчисления!$K$188*30+ROW()-1) -> 13.6 | AB8: Isol, хор | AC8: W/m2 | AD8: =INDIRECT("ad"&Изчисления!$K$188*30+ROW()-1) -> 53.5 | AE8: =INDIRECT("ae"&Изчисления!$K$188*30+ROW()-1) -> 88.5 | AF8: =INDIRECT("af"&Изчисления!$K$188*30+ROW()-1) -> 118.7 | AG8: =INDIRECT("ag"&Изчисления!$K$188*30+ROW()-1) -> 116.4 | AH8: =INDIRECT("ah"&Изчисления!$K$188*30+ROW()-1) -> 106 | AI8: =INDIRECT("ai"&Изчисления!$K$188*30+ROW()-1) -> 62.8 | AJ8: =INDIRECT("aj"&Изчисления!$K$188*30+ROW()-1) -> 46.3
B9: φе | C9: % | D9: =INDIRECT("D"&Изчисления!$K$188*30+ROW()-1) -> 78 | E9: =INDIRECT("E"&Изчисления!$K$188*30+ROW()-1) -> 77 | F9: =INDIRECT("f"&Изчисления!$K$188*30+ROW()-1) -> 79 | G9: =INDIRECT("g"&Изчисления!$K$188*30+ROW()-1) -> 80 | H9: =INDIRECT("h"&Изчисления!$K$188*30+ROW()-1) -> 81 | I9: =INDIRECT("i"&Изчисления!$K$188*30+ROW()-1) -> 79 | J9: =INDIRECT("j"&Изчисления!$K$188*30+ROW()-1) -> 76 | K9: =INDIRECT("k"&Изчисления!$K$188*30+ROW()-1) -> 74 | L9: =INDIRECT("l"&Изчисления!$K$188*30+ROW()-1) -> 71 | M9: =INDIRECT("m"&Изчисления!$K$188*30+ROW()-1) -> 68 | N9: =INDIRECT("n"&Изчисления!$K$188*30+ROW()-1) -> 65 | O9: =INDIRECT("o"&Изчисления!$K$188*30+ROW()-1) -> 66 | P9: =INDIRECT("p"&Изчисления!$K$188*30+ROW()-1) -> 67 | Q9: =INDIRECT("q"&Изчисления!$K$188*30+ROW()-1) -> 68 | R9: =INDIRECT("r"&Изчисления!$K$188*30+ROW()-1) -> 69 | S9: =INDIRECT("s"&Изчисления!$K$188*30+ROW()-1) -> 69 | T9: =INDIRECT("t"&Изчисления!$K$188*30+ROW()-1) -> 70 | U9: =INDIRECT("u"&Изчисления!$K$188*30+ROW()-1) -> 73 | V9: =INDIRECT("v"&Изчисления!$K$188*30+ROW()-1) -> 75 | W9: =INDIRECT("w"&Изчисления!$K$188*30+ROW()-1) -> 78 | X9: =INDIRECT("x"&Изчисления!$K$188*30+ROW()-1) -> 78 | Y9: =INDIRECT("y"&Изчисления!$K$188*30+ROW()-1) -> 78 | Z9: =INDIRECT("z"&Изчисления!$K$188*30+ROW()-1) -> 77 | AA9: =INDIRECT("aa"&Изчисления!$K$188*30+ROW()-1) -> 78 | AC9: темп | AD9: =INDIRECT("ad"&Изчисления!$K$188*30+ROW()-1) -> 2.2 | AE9: =INDIRECT("ae"&Изчисления!$K$188*30+ROW()-1) -> 2.9 | AF9: =INDIRECT("af"&Изчисления!$K$188*30+ROW()-1) -> 5.7 | AG9: =INDIRECT("ag"&Изчисления!$K$188*30+ROW()-1) -> 10.9 | AH9: =INDIRECT("ah"&Изчисления!$K$188*30+ROW()-1) -> 14.5 | AI9: =INDIRECT("ai"&Изчисления!$K$188*30+ROW()-1) -> 9.4 | AJ9: =INDIRECT("aj"&Изчисления!$K$188*30+ROW()-1) -> 4.6
A10: Юни | B10: θе | C10: C | D10: =INDIRECT("D"&Изчисления!$K$188*30+ROW()-1) -> 16 | E10: =INDIRECT("E"&Изчисления!$K$188*30+ROW()-1) -> 16.8 | F10: =INDIRECT("f"&Изчисления!$K$188*30+ROW()-1) -> 15.8 | G10: =INDIRECT("g"&Изчисления!$K$188*30+ROW()-1) -> 15.3 | H10: =INDIRECT("h"&Изчисления!$K$188*30+ROW()-1) -> 16.1 | I10: =INDIRECT("i"&Изчисления!$K$188*30+ROW()-1) -> 15.9 | J10: =INDIRECT("j"&Изчисления!$K$188*30+ROW()-1) -> 17.8 | K10: =INDIRECT("k"&Изчисления!$K$188*30+ROW()-1) -> 19 | L10: =INDIRECT("l"&Изчисления!$K$188*30+ROW()-1) -> 21.3 | M10: =INDIRECT("m"&Изчисления!$K$188*30+ROW()-1) -> 22.5 | N10: =INDIRECT("n"&Изчисления!$K$188*30+ROW()-1) -> 22.3 | O10: =INDIRECT("o"&Изчисления!$K$188*30+ROW()-1) -> 23.8 | P10: =INDIRECT("p"&Изчисления!$K$188*30+ROW()-1) -> 23.9 | Q10: =INDIRECT("q"&Изчисления!$K$188*30+ROW()-1) -> 23.3 | R10: =INDIRECT("r"&Изчисления!$K$188*30+ROW()-1) -> 24.1 | S10: =INDIRECT("s"&Изчисления!$K$188*30+ROW()-1) -> 23.8 | T10: =INDIRECT("t"&Изчисления!$K$188*30+ROW()-1) -> 22.3 | U10: =INDIRECT("u"&Изчисления!$K$188*30+ROW()-1) -> 22.2 | V10: =INDIRECT("v"&Изчисления!$K$188*30+ROW()-1) -> 20.9 | W10: =INDIRECT("w"&Изчисления!$K$188*30+ROW()-1) -> 19.5 | X10: =INDIRECT("x"&Изчисления!$K$188*30+ROW()-1) -> 17.8 | Y10: =INDIRECT("y"&Изчисления!$K$188*30+ROW()-1) -> 17.6 | Z10: =INDIRECT("z"&Изчисления!$K$188*30+ROW()-1) -> 17.4 | AA10: =INDIRECT("aa"&Изчисления!$K$188*30+ROW()-1) -> 16.4 | AB10: Летен период
B11: φе | C11: % | D11: =INDIRECT("D"&Изчисления!$K$188*30+ROW()-1) -> 89 | E11: =INDIRECT("E"&Изчисления!$K$188*30+ROW()-1) -> 89 | F11: =INDIRECT("f"&Изчисления!$K$188*30+ROW()-1) -> 90 | G11: =INDIRECT("g"&Изчисления!$K$188*30+ROW()-1) -> 91 | H11: =INDIRECT("h"&Изчисления!$K$188*30+ROW()-1) -> 88 | I11: =INDIRECT("i"&Изчисления!$K$188*30+ROW()-1) -> 89 | J11: =INDIRECT("j"&Изчисления!$K$188*30+ROW()-1) -> 83 | K11: =INDIRECT("k"&Изчисления!$K$188*30+ROW()-1) -> 79 | L11: =INDIRECT("l"&Изчисления!$K$188*30+ROW()-1) -> 69 | M11: =INDIRECT("m"&Изчисления!$K$188*30+ROW()-1) -> 65 | N11: =INDIRECT("n"&Изчисления!$K$188*30+ROW()-1) -> 71 | O11: =INDIRECT("o"&Изчисления!$K$188*30+ROW()-1) -> 59 | P11: =INDIRECT("p"&Изчисления!$K$188*30+ROW()-1) -> 60 | Q11: =INDIRECT("q"&Изчисления!$K$188*30+ROW()-1) -> 70 | R11: =INDIRECT("r"&Изчисления!$K$188*30+ROW()-1) -> 59 | S11: =INDIRECT("s"&Изчисления!$K$188*30+ROW()-1) -> 59 | T11: =INDIRECT("t"&Изчисления!$K$188*30+ROW()-1) -> 73 | U11: =INDIRECT("u"&Изчисления!$K$188*30+ROW()-1) -> 65 | V11: =INDIRECT("v"&Изчисления!$K$188*30+ROW()-1) -> 72 | W11: =INDIRECT("w"&Изчисления!$K$188*30+ROW()-1) -> 82 | X11: =INDIRECT("x"&Изчисления!$K$188*30+ROW()-1) -> 86 | Y11: =INDIRECT("y"&Изчисления!$K$188*30+ROW()-1) -> 87 | Z11: =INDIRECT("z"&Изчисления!$K$188*30+ROW()-1) -> 89 | AA11: =INDIRECT("aa"&Изчисления!$K$188*30+ROW()-1) -> 88 | AB11: Isol, с | AC11: W/m2 | AD11: =INDIRECT("ad"&Изчисления!$K$188*30+ROW()-1) -> 79.3 | AE11: =INDIRECT("ae"&Изчисления!$K$188*30+ROW()-1) -> 85.4 | AF11: =INDIRECT("af"&Изчисления!$K$188*30+ROW()-1) -> 84.2 | AG11: =INDIRECT("ag"&Изчисления!$K$188*30+ROW()-1) -> 75.6 | AH11: =INDIRECT("ah"&Изчисления!$K$188*30+ROW()-1) -> 60.6
A12: Юли | B12: θе | C12: C | D12: =INDIRECT("D"&Изчисления!$K$188*30+ROW()-1) -> 18.8 | E12: =INDIRECT("E"&Изчисления!$K$188*30+ROW()-1) -> 19.8 | F12: =INDIRECT("f"&Изчисления!$K$188*30+ROW()-1) -> 18.5 | G12: =INDIRECT("g"&Изчисления!$K$188*30+ROW()-1) -> 18.2 | H12: =INDIRECT("h"&Изчисления!$K$188*30+ROW()-1) -> 19.2 | I12: =INDIRECT("i"&Изчисления!$K$188*30+ROW()-1) -> 18.5 | J12: =INDIRECT("j"&Изчисления!$K$188*30+ROW()-1) -> 20.5 | K12: =INDIRECT("k"&Изчисления!$K$188*30+ROW()-1) -> 22 | L12: =INDIRECT("l"&Изчисления!$K$188*30+ROW()-1) -> 24.1 | M12: =INDIRECT("m"&Изчисления!$K$188*30+ROW()-1) -> 25.5 | N12: =INDIRECT("n"&Изчисления!$K$188*30+ROW()-1) -> 25.9 | O12: =INDIRECT("o"&Изчисления!$K$188*30+ROW()-1) -> 26.6 | P12: =INDIRECT("p"&Изчисления!$K$188*30+ROW()-1) -> 26.8 | Q12: =INDIRECT("q"&Изчисления!$K$188*30+ROW()-1) -> 26.5 | R12: =INDIRECT("r"&Изчисления!$K$188*30+ROW()-1) -> 26.8 | S12: =INDIRECT("s"&Изчисления!$K$188*30+ROW()-1) -> 26.5 | T12: =INDIRECT("t"&Изчисления!$K$188*30+ROW()-1) -> 25.7 | U12: =INDIRECT("u"&Изчисления!$K$188*30+ROW()-1) -> 25.1 | V12: =INDIRECT("v"&Изчисления!$K$188*30+ROW()-1) -> 24 | W12: =INDIRECT("w"&Изчисления!$K$188*30+ROW()-1) -> 22.9 | X12: =INDIRECT("x"&Изчисления!$K$188*30+ROW()-1) -> 21.1 | Y12: =INDIRECT("y"&Изчисления!$K$188*30+ROW()-1) -> 20.2 | Z12: =INDIRECT("z"&Изчисления!$K$188*30+ROW()-1) -> 20.8 | AA12: =INDIRECT("aa"&Изчисления!$K$188*30+ROW()-1) -> 19.1 | AB12: Isol, и | AC12: W/m2 | AD12: =INDIRECT("ad"&Изчисления!$K$188*30+ROW()-1) -> 115.5 | AE12: =INDIRECT("ae"&Изчисления!$K$188*30+ROW()-1) -> 129.3 | AF12: =INDIRECT("af"&Изчисления!$K$188*30+ROW()-1) -> 133.9 | AG12: =INDIRECT("ag"&Изчисления!$K$188*30+ROW()-1) -> 134.3 | AH12: =INDIRECT("ah"&Изчисления!$K$188*30+ROW()-1) -> 113.3
B13: φе | C13: % | D13: =INDIRECT("D"&Изчисления!$K$188*30+ROW()-1) -> 87 | E13: =INDIRECT("E"&Изчисления!$K$188*30+ROW()-1) -> 82 | F13: =INDIRECT("f"&Изчисления!$K$188*30+ROW()-1) -> 89 | G13: =INDIRECT("g"&Изчисления!$K$188*30+ROW()-1) -> 89 | H13: =INDIRECT("h"&Изчисления!$K$188*30+ROW()-1) -> 83 | I13: =INDIRECT("i"&Изчисления!$K$188*30+ROW()-1) -> 88 | J13: =INDIRECT("j"&Изчисления!$K$188*30+ROW()-1) -> 81 | K13: =INDIRECT("k"&Изчисления!$K$188*30+ROW()-1) -> 77 | L13: =INDIRECT("l"&Изчисления!$K$188*30+ROW()-1) -> 68 | M13: =INDIRECT("m"&Изчисления!$K$188*30+ROW()-1) -> 61 | N13: =INDIRECT("n"&Изчисления!$K$188*30+ROW()-1) -> 65 | O13: =INDIRECT("o"&Изчисления!$K$188*30+ROW()-1) -> 55 | P13: =INDIRECT("p"&Изчисления!$K$188*30+ROW()-1) -> 56 | Q13: =INDIRECT("q"&Изчисления!$K$188*30+ROW()-1) -> 65 | R13: =INDIRECT("r"&Изчисления!$K$188*30+ROW()-1) -> 55 | S13: =INDIRECT("s"&Изчисления!$K$188*30+ROW()-1) -> 57 | T13: =INDIRECT("t"&Изчисления!$K$188*30+ROW()-1) -> 67 | U13: =INDIRECT("u"&Изчисления!$K$188*30+ROW()-1) -> 62 | V13: =INDIRECT("v"&Изчисления!$K$188*30+ROW()-1) -> 66 | W13: =INDIRECT("w"&Изчисления!$K$188*30+ROW()-1) -> 74 | X13: =INDIRECT("x"&Изчисления!$K$188*30+ROW()-1) -> 80 | Y13: =INDIRECT("y"&Изчисления!$K$188*30+ROW()-1) -> 84 | Z13: =INDIRECT("z"&Изчисления!$K$188*30+ROW()-1) -> 81 | AA13: =INDIRECT("aa"&Изчисления!$K$188*30+ROW()-1) -> 86 | AB13: Isol, ю | AC13: W/m2 | AD13: =INDIRECT("ad"&Изчисления!$K$188*30+ROW()-1) -> 97.1 | AE13: =INDIRECT("ae"&Изчисления!$K$188*30+ROW()-1) -> 103.7 | AF13: =INDIRECT("af"&Изчисления!$K$188*30+ROW()-1) -> 112 | AG13: =INDIRECT("ag"&Изчисления!$K$188*30+ROW()-1) -> 136.8 | AH13: =INDIRECT("ah"&Изчисления!$K$188*30+ROW()-1) -> 148.2
A14: Август | B14: θе | C14: C | D14: =INDIRECT("D"&Изчисления!$K$188*30+ROW()-1) -> 19.1 | E14: =INDIRECT("E"&Изчисления!$K$188*30+ROW()-1) -> 18.8 | F14: =INDIRECT("f"&Изчисления!$K$188*30+ROW()-1) -> 18.5 | G14: =INDIRECT("g"&Изчисления!$K$188*30+ROW()-1) -> 18.3 | H14: =INDIRECT("h"&Изчисления!$K$188*30+ROW()-1) -> 18 | I14: =INDIRECT("i"&Изчисления!$K$188*30+ROW()-1) -> 18.7 | J14: =INDIRECT("j"&Изчисления!$K$188*30+ROW()-1) -> 19.5 | K14: =INDIRECT("k"&Изчисления!$K$188*30+ROW()-1) -> 20 | L14: =INDIRECT("l"&Изчисления!$K$188*30+ROW()-1) -> 21.5 | M14: =INDIRECT("m"&Изчисления!$K$188*30+ROW()-1) -> 22.9 | N14: =INDIRECT("n"&Изчисления!$K$188*30+ROW()-1) -> 24.3 | O14: =INDIRECT("o"&Изчисления!$K$188*30+ROW()-1) -> 24.6 | P14: =INDIRECT("p"&Изчисления!$K$188*30+ROW()-1) -> 24.9 | Q14: =INDIRECT("q"&Изчисления!$K$188*30+ROW()-1) -> 25.3 | R14: =INDIRECT("r"&Изчисления!$K$188*30+ROW()-1) -> 25.1 | S14: =INDIRECT("s"&Изчисления!$K$188*30+ROW()-1) -> 24.8 | T14: =INDIRECT("t"&Изчисления!$K$188*30+ROW()-1) -> 24.5 | U14: =INDIRECT("u"&Изчисления!$K$188*30+ROW()-1) -> 23.5 | V14: =INDIRECT("v"&Изчисления!$K$188*30+ROW()-1) -> 22.5 | W14: =INDIRECT("w"&Изчисления!$K$188*30+ROW()-1) -> 21.5 | X14: =INDIRECT("x"&Изчисления!$K$188*30+ROW()-1) -> 20.9 | Y14: =INDIRECT("y"&Изчисления!$K$188*30+ROW()-1) -> 20.3 | Z14: =INDIRECT("z"&Изчисления!$K$188*30+ROW()-1) -> 19.8 | AA14: =INDIRECT("aa"&Изчисления!$K$188*30+ROW()-1) -> 19.5 | AB14: Isol, з | AC14: W/m2 | AD14: =INDIRECT("ad"&Изчисления!$K$188*30+ROW()-1) -> 115.5 | AE14: =INDIRECT("ae"&Изчисления!$K$188*30+ROW()-1) -> 129.3 | AF14: =INDIRECT("af"&Изчисления!$K$188*30+ROW()-1) -> 133.9 | AG14: =INDIRECT("ag"&Изчисления!$K$188*30+ROW()-1) -> 134.3 | AH14: =INDIRECT("ah"&Изчисления!$K$188*30+ROW()-1) -> 113.3
B15: φе | C15: % | D15: =INDIRECT("D"&Изчисления!$K$188*30+ROW()-1) -> 87 | E15: =INDIRECT("E"&Изчисления!$K$188*30+ROW()-1) -> 87 | F15: =INDIRECT("f"&Изчисления!$K$188*30+ROW()-1) -> 89 | G15: =INDIRECT("g"&Изчисления!$K$188*30+ROW()-1) -> 89 | H15: =INDIRECT("h"&Изчисления!$K$188*30+ROW()-1) -> 90 | I15: =INDIRECT("i"&Изчисления!$K$188*30+ROW()-1) -> 89 | J15: =INDIRECT("j"&Изчисления!$K$188*30+ROW()-1) -> 87 | K15: =INDIRECT("k"&Изчисления!$K$188*30+ROW()-1) -> 85 | L15: =INDIRECT("l"&Изчисления!$K$188*30+ROW()-1) -> 81 | M15: =INDIRECT("m"&Изчисления!$K$188*30+ROW()-1) -> 77 | N15: =INDIRECT("n"&Изчисления!$K$188*30+ROW()-1) -> 73 | O15: =INDIRECT("o"&Изчисления!$K$188*30+ROW()-1) -> 72 | P15: =INDIRECT("p"&Изчисления!$K$188*30+ROW()-1) -> 71 | Q15: =INDIRECT("q"&Изчисления!$K$188*30+ROW()-1) -> 68 | R15: =INDIRECT("r"&Изчисления!$K$188*30+ROW()-1) -> 70 | S15: =INDIRECT("s"&Изчисления!$K$188*30+ROW()-1) -> 71 | T15: =INDIRECT("t"&Изчисления!$K$188*30+ROW()-1) -> 72 | U15: =INDIRECT("u"&Изчисления!$K$188*30+ROW()-1) -> 75 | V15: =INDIRECT("v"&Изчисления!$K$188*30+ROW()-1) -> 78 | W15: =INDIRECT("w"&Изчисления!$K$188*30+ROW()-1) -> 81 | X15: =INDIRECT("x"&Изчисления!$K$188*30+ROW()-1) -> 83 | Y15: =INDIRECT("y"&Изчисления!$K$188*30+ROW()-1) -> 85 | Z15: =INDIRECT("z"&Изчисления!$K$188*30+ROW()-1) -> 86 | AA15: =INDIRECT("aa"&Изчисления!$K$188*30+ROW()-1) -> 87 | AB15: Isol, хор | AC15: W/m2 | AD15: =INDIRECT("ad"&Изчисления!$K$188*30+ROW()-1) -> 206.9 | AE15: =INDIRECT("ae"&Изчисления!$K$188*30+ROW()-1) -> 231.2 | AF15: =INDIRECT("af"&Изчисления!$K$188*30+ROW()-1) -> 239.9 | AG15: =INDIRECT("ag"&Изчисления!$K$188*30+ROW()-1) -> 233 | AH15: =INDIRECT("ah"&Изчисления!$K$188*30+ROW()-1) -> 178.7
A16: Септември | B16: θе | C16: C | D16: =INDIRECT("D"&Изчисления!$K$188*30+ROW()-1) -> 15.3 | E16: =INDIRECT("E"&Изчисления!$K$188*30+ROW()-1) -> 15.5 | F16: =INDIRECT("f"&Изчисления!$K$188*30+ROW()-1) -> 15.2 | G16: =INDIRECT("g"&Изчисления!$K$188*30+ROW()-1) -> 14.7 | H16: =INDIRECT("h"&Изчисления!$K$188*30+ROW()-1) -> 14.7 | I16: =INDIRECT("i"&Изчисления!$K$188*30+ROW()-1) -> 14.6 | J16: =INDIRECT("j"&Изчисления!$K$188*30+ROW()-1) -> 15.5 | K16: =INDIRECT("k"&Изчисления!$K$188*30+ROW()-1) -> 16.7 | L16: =INDIRECT("l"&Изчисления!$K$188*30+ROW()-1) -> 18.4 | M16: =INDIRECT("m"&Изчисления!$K$188*30+ROW()-1) -> 20.1 | N16: =INDIRECT("n"&Изчисления!$K$188*30+ROW()-1) -> 21.8 | O16: =INDIRECT("o"&Изчисления!$K$188*30+ROW()-1) -> 22 | P16: =INDIRECT("p"&Изчисления!$K$188*30+ROW()-1) -> 22.8 | Q16: =INDIRECT("q"&Изчисления!$K$188*30+ROW()-1) -> 23.1 | R16: =INDIRECT("r"&Изчисления!$K$188*30+ROW()-1) -> 22.7 | S16: =INDIRECT("s"&Изчисления!$K$188*30+ROW()-1) -> 22.2 | T16: =INDIRECT("t"&Изчисления!$K$188*30+ROW()-1) -> 21.3 | U16: =INDIRECT("u"&Изчисления!$K$188*30+ROW()-1) -> 20.5 | V16: =INDIRECT("v"&Изчисления!$K$188*30+ROW()-1) -> 19.2 | W16: =INDIRECT("w"&Изчисления!$K$188*30+ROW()-1) -> 17.9 | X16: =INDIRECT("x"&Изчисления!$K$188*30+ROW()-1) -> 17.3 | Y16: =INDIRECT("y"&Изчисления!$K$188*30+ROW()-1) -> 16.5 | Z16: =INDIRECT("z"&Изчисления!$K$188*30+ROW()-1) -> 16.5 | AA16: =INDIRECT("aa"&Изчисления!$K$188*30+ROW()-1) -> 15.7 | AD16: =INDIRECT("ad"&Изчисления!$K$188*30+ROW()-1) -> 16 | AE16: =INDIRECT("ae"&Изчисления!$K$188*30+ROW()-1) -> 20.6 | AF16: =INDIRECT("af"&Изчисления!$K$188*30+ROW()-1) -> 23.4 | AG16: =INDIRECT("ag"&Изчисления!$K$188*30+ROW()-1) -> 23.1 | AH16: =INDIRECT("ah"&Изчисления!$K$188*30+ROW()-1) -> 19.7
B17: φе | C17: % | D17: =INDIRECT("D"&Изчисления!$K$188*30+ROW()-1) -> 80 | E17: =INDIRECT("E"&Изчисления!$K$188*30+ROW()-1) -> 79 | F17: =INDIRECT("f"&Изчисления!$K$188*30+ROW()-1) -> 80 | G17: =INDIRECT("g"&Изчисления!$K$188*30+ROW()-1) -> 81 | H17: =INDIRECT("h"&Изчисления!$K$188*30+ROW()-1) -> 80 | I17: =INDIRECT("i"&Изчисления!$K$188*30+ROW()-1) -> 80 | J17: =INDIRECT("j"&Изчисления!$K$188*30+ROW()-1) -> 78 | K17: =INDIRECT("k"&Изчисления!$K$188*30+ROW()-1) -> 73 | L17: =INDIRECT("l"&Изчисления!$K$188*30+ROW()-1) -> 67 | M17: =INDIRECT("m"&Изчисления!$K$188*30+ROW()-1) -> 61 | N17: =INDIRECT("n"&Изчисления!$K$188*30+ROW()-1) -> 58 | O17: =INDIRECT("o"&Изчисления!$K$188*30+ROW()-1) -> 56 | P17: =INDIRECT("p"&Изчисления!$K$188*30+ROW()-1) -> 55 | Q17: =INDIRECT("q"&Изчисления!$K$188*30+ROW()-1) -> 56 | R17: =INDIRECT("r"&Изчисления!$K$188*30+ROW()-1) -> 55 | S17: =INDIRECT("s"&Изчисления!$K$188*30+ROW()-1) -> 58 | T17: =INDIRECT("t"&Изчисления!$K$188*30+ROW()-1) -> 63 | U17: =INDIRECT("u"&Изчисления!$K$188*30+ROW()-1) -> 64 | V17: =INDIRECT("v"&Изчисления!$K$188*30+ROW()-1) -> 68 | W17: =INDIRECT("w"&Изчисления!$K$188*30+ROW()-1) -> 73 | X17: =INDIRECT("x"&Изчисления!$K$188*30+ROW()-1) -> 74 | Y17: =INDIRECT("y"&Изчисления!$K$188*30+ROW()-1) -> 78 | Z17: =INDIRECT("z"&Изчисления!$K$188*30+ROW()-1) -> 77 | AA17: =INDIRECT("aa"&Изчисления!$K$188*30+ROW()-1) -> 79 | AE17: =INDIRECT("ae"&Изчисления!$K$188*30+ROW()-1) -> 5 | AF17: № на климатична зона
A18: Октомври | B18: θе | C18: C | D18: =IF(Изчисления!$K$196=1,$M$21,INDIRECT("D"&Изчисления!$K$188*30+ROW()-1)) -> 14.5 | E18: =IF(Изчисления!$K$196=1,$M$21,INDIRECT("D"&Изчисления!$K$188*30+ROW()-1)) -> 14.5 | F18: =IF(Изчисления!$K$196=1,$M$21,INDIRECT("D"&Изчисления!$K$188*30+ROW()-1)) -> 14.5 | G18: =IF(Изчисления!$K$196=1,$M$21,INDIRECT("D"&Изчисления!$K$188*30+ROW()-1)) -> 14.5 | H18: =IF(Изчисления!$K$196=1,$M$21,INDIRECT("D"&Изчисления!$K$188*30+ROW()-1)) -> 14.5 | I18: =IF(Изчисления!$K$196=1,$M$21,INDIRECT("D"&Изчисления!$K$188*30+ROW()-1)) -> 14.5 | J18: =IF(Изчисления!$K$196=1,$M$21,INDIRECT("D"&Изчисления!$K$188*30+ROW()-1)) -> 14.5 | K18: =IF(Изчисления!$K$196=1,$M$21,INDIRECT("D"&Изчисления!$K$188*30+ROW()-1)) -> 14.5 | ... AA18: =IF(Изчисления!$K$196=1,$M$21,INDIRECT("D"&Изчисления!$K$188*30+ROW()-1)) -> 14.5 | AB18: DD | AE18: θе= | AF18: =INDIRECT("af"&Изчисления!$K$188*30+ROW()-1) -> 2.2 | AG18: януари средна месечна
A19: Ноември | B19: θе | C19: C | D19: =IF(Изчисления!$K$196=1,$N$21,INDIRECT("D"&Изчисления!$K$188*30+ROW()-1)) -> 9.4 | E19: =IF(Изчисления!$K$196=1,$N$21,INDIRECT("D"&Изчисления!$K$188*30+ROW()-1)) -> 9.4 | F19: =IF(Изчисления!$K$196=1,$N$21,INDIRECT("D"&Изчисления!$K$188*30+ROW()-1)) -> 9.4 | G19: =IF(Изчисления!$K$196=1,$N$21,INDIRECT("D"&Изчисления!$K$188*30+ROW()-1)) -> 9.4 | H19: =IF(Изчисления!$K$196=1,$N$21,INDIRECT("D"&Изчисления!$K$188*30+ROW()-1)) -> 9.4 | I19: =IF(Изчисления!$K$196=1,$N$21,INDIRECT("D"&Изчисления!$K$188*30+ROW()-1)) -> 9.4 | J19: =IF(Изчисления!$K$196=1,$N$21,INDIRECT("D"&Изчисления!$K$188*30+ROW()-1)) -> 9.4 | K19: =IF(Изчисления!$K$196=1,$N$21,INDIRECT("D"&Изчисления!$K$188*30+ROW()-1)) -> 9.4 | ... AA19: =IF(Изчисления!$K$196=1,$N$21,INDIRECT("D"&Изчисления!$K$188*30+ROW()-1)) -> 9.4 | AB19: =INDIRECT("ab"&Изчисления!$K$188*30+ROW()-1) -> 2300 | AE19: =INDIRECT("ae"&Изчисления!$K$188*30+ROW()-1) -> 25 | AF19: октомври
A20: Декември | B20: θе | C20: C | D20: =IF(Изчисления!$K$196=1,$O$21,INDIRECT("D"&Изчисления!$K$188*30+ROW()-1)) -> 4.6 | E20: =IF(Изчисления!$K$196=1,$O$21,INDIRECT("D"&Изчисления!$K$188*30+ROW()-1)) -> 4.6 | F20: =IF(Изчисления!$K$196=1,$O$21,INDIRECT("D"&Изчисления!$K$188*30+ROW()-1)) -> 4.6 | G20: =IF(Изчисления!$K$196=1,$O$21,INDIRECT("D"&Изчисления!$K$188*30+ROW()-1)) -> 4.6 | H20: =IF(Изчисления!$K$196=1,$O$21,INDIRECT("D"&Изчисления!$K$188*30+ROW()-1)) -> 4.6 | I20: =IF(Изчисления!$K$196=1,$O$21,INDIRECT("D"&Изчисления!$K$188*30+ROW()-1)) -> 4.6 | J20: =IF(Изчисления!$K$196=1,$O$21,INDIRECT("D"&Изчисления!$K$188*30+ROW()-1)) -> 4.6 | K20: =IF(Изчисления!$K$196=1,$O$21,INDIRECT("D"&Изчисления!$K$188*30+ROW()-1)) -> 4.6 | ... AA20: =IF(Изчисления!$K$196=1,$O$21,INDIRECT("D"&Изчисления!$K$188*30+ROW()-1)) -> 4.6 | AE20: =INDIRECT("ae"&Изчисления!$K$188*30+ROW()-1) -> 19 | AF20: април
A21: Среднмес. Темп | C21: С | D21: =INDIRECT("D"&Изчисления!$K$188*30+ROW()-1) -> 2.2 | E21: =INDIRECT("E"&Изчисления!$K$188*30+ROW()-1) -> 2.9 | F21: =INDIRECT("f"&Изчисления!$K$188*30+ROW()-1) -> 5.7 | G21: =INDIRECT("g"&Изчисления!$K$188*30+ROW()-1) -> 10.9 | H21: =INDIRECT("h"&Изчисления!$K$188*30+ROW()-1) -> 16 | I21: =INDIRECT("i"&Изчисления!$K$188*30+ROW()-1) -> 20.6 | J21: =INDIRECT("j"&Изчисления!$K$188*30+ROW()-1) -> 23.4 | K21: =INDIRECT("k"&Изчисления!$K$188*30+ROW()-1) -> 23.1 | L21: =INDIRECT("l"&Изчисления!$K$188*30+ROW()-1) -> 19.7 | M21: =INDIRECT("m"&Изчисления!$K$188*30+ROW()-1) -> 14.5 | N21: =INDIRECT("n"&Изчисления!$K$188*30+ROW()-1) -> 9.4 | O21: =INDIRECT("o"&Изчисления!$K$188*30+ROW()-1) -> 4.6 | X21: =INDIRECT("x"&Изчисления!$K$188*30+ROW()-1) -> HT | Y21: =INDIRECT("y"&Изчисления!$K$188*30+ROW()-1) -> 1.28 | Z21: =INDIRECT("z"&Изчисления!$K$188*30+ROW()-1) -> 2.12 | AA21: =INDIRECT("aa"&Изчисления!$K$188*30+ROW()-1) -> 2.85 | AB21: =INDIRECT("ab"&Изчисления!$K$188*30+ROW()-1) -> 3.87 | AC21: =INDIRECT("ac"&Изчисления!$K$188*30+ROW()-1) -> 4.97 | AD21: =INDIRECT("ad"&Изчисления!$K$188*30+ROW()-1) -> 5.55 | AE21: =INDIRECT("ae"&Изчисления!$K$188*30+ROW()-1) -> 5.76 | AF21: =INDIRECT("af"&Изчисления!$K$188*30+ROW()-1) -> 5.59 | AG21: =INDIRECT("ag"&Изчисления!$K$188*30+ROW()-1) -> 4.29 | AH21: =INDIRECT("ah"&Изчисления!$K$188*30+ROW()-1) -> 2.54 | AI21: =INDIRECT("ai"&Изчисления!$K$188*30+ROW()-1) -> 1.51 | AJ21: =INDIRECT("aj"&Изчисления!$K$188*30+ROW()-1) -> 1.11
X22: =INDIRECT("x"&Изчисления!$K$188*30+ROW()-1) -> KT | Y22: =INDIRECT("y"&Изчисления!$K$188*30+ROW()-1) -> 0.34 | Z22: =INDIRECT("z"&Изчисления!$K$188*30+ROW()-1) -> 0.41 | AA22: =INDIRECT("aa"&Изчисления!$K$188*30+ROW()-1) -> 0.43 | AB22: =INDIRECT("ab"&Изчисления!$K$188*30+ROW()-1) -> 0.42 | AC22: =INDIRECT("ac"&Изчисления!$K$188*30+ROW()-1) -> 0.46 | AD22: =INDIRECT("ad"&Изчисления!$K$188*30+ROW()-1) -> 0.49 | AE22: =INDIRECT("ae"&Изчисления!$K$188*30+ROW()-1) -> 0.52 | AF22: =INDIRECT("af"&Изчисления!$K$188*30+ROW()-1) -> 0.57 | AG22: =INDIRECT("ag"&Изчисления!$K$188*30+ROW()-1) -> 0.54 | AH22: =INDIRECT("ah"&Изчисления!$K$188*30+ROW()-1) -> 0.44 | AI22: =INDIRECT("ai"&Изчисления!$K$188*30+ROW()-1) -> 0.37 | AJ22: =INDIRECT("aj"&Изчисления!$K$188*30+ROW()-1) -> 0.33
A30: Климатична зона №1
B32: Час | C32: - | D32: 0 | E32: 1 | F32: 2 | G32: 3 | H32: 4 | I32: 5 | J32: 6 | K32: 7 | L32: 8 | M32: 9 | N32: 10 | O32: 11 | P32: 12 | Q32: 13 | R32: 14 | S32: 15 | T32: 16 | U32: 17 | V32: 18 | W32: 19 | X32: 20 | Y32: 21 | Z32: 22 | AA32: 23 | AB32: Зимен период
A33: Януари | B33: θе | C33: C | D33: 2.8 | E33: 2.5 | F33: 2.3 | G33: 2.3 | H33: 2.2 | I33: 2 | J33: 1.9 | K33: 2 | L33: 2.6 | M33: 3.5 | N33: 4.6 | O33: 5.1 | P33: 5.7 | Q33: 5.9 | R33: 5.6 | S33: 5.1 | T33: 4.7 | U33: 4 | V33: 3.6 | W33: 3.4 | X33: 2.9 | Y33: 2.9 | Z33: 3 | AA33: 2.7 | AB33: Isol, с | AC33: W/m2 | AD33: 22.9 | AE33: 34.8 | AF33: 47.7 | AG33: 63.6 | AH33: 40.9 | AI33: 26.1 | AJ33: 20.2
A34: Февруари | B34: θе | C34: C | D34: 1.7 | E34: 1.6 | F34: 1.6 | G34: 1.6 | H34: 1.9 | I34: 1.8 | J34: 1.7 | K34: 1.7 | L34: 2.5 | M34: 3.7 | N34: 4.9 | O34: 5.4 | P34: 6 | Q34: 6.7 | R34: 6.4 | S34: 6 | T34: 5.6 | U34: 4.8 | V34: 4.1 | W34: 3.5 | X34: 3 | Y34: 2.5 | Z34: 2.5 | AA34: 2.3 | AB34: Isol, и | AC34: W/m2 | AD34: 40.4 | AE34: 59.2 | AF34: 68.4 | AG34: 85.5 | AH34: 68 | AI34: 45.8 | AJ34: 36.6
A35: Март | B35: θе | C35: C | D35: 3.7 | E35: 3.7 | F35: 3.6 | G35: 3.5 | H35: 3.4 | I35: 3.5 | J35: 3.6 | K35: 3.7 | L35: 4.5 | M35: 5.4 | N35: 6.3 | O35: 6.6 | P35: 7 | Q35: 7.4 | R35: 7.1 | S35: 6.8 | T35: 6.4 | U35: 5.9 | V35: 5.3 | W35: 4.8 | X35: 4.5 | Y35: 4.3 | Z35: 4 | AA35: 3.9 | AB35: Isol, ю | AC35: W/m2 | AD35: 72.7 | AE35: 95.9 | AF35: 87.5 | AG35: 83.7 | AH35: 104.3 | AI35: 80.6 | AJ35: 67.8
A36: Април | B36: θе | C36: C | D36: 8 | E36: 8 | F36: 7.6 | G36: 7.5 | H36: 7.4 | I36: 7.4 | J36: 8.4 | K36: 9.5 | L36: 11 | M36: 12 | N36: 13 | O36: 13 | P36: 13 | Q36: 13 | R36: 13 | S36: 13 | T36: 12 | U36: 11 | V36: 11 | W36: 9.8 | X36: 9.3 | Y36: 9.1 | Z36: 8.8 | AA36: 8.5 | AB36: Isol, з | AC36: W/m2 | AD36: 40.4 | AE36: 59.2 | AF36: 68.4 | AG36: 85.5 | AH36: 68 | AI36: 45.8 | AJ36: 36.6
A37: Май | B37: θе | C37: C | D37: 13.3 | E37: 13.1 | F37: 12.9 | G37: 12.7 | H37: 12.5 | I37: 13.4 | J37: 14.3 | K37: 15.2 | L37: 16.1 | M37: 17.2 | N37: 18.2 | O37: 18.1 | P37: 18.1 | Q37: 18.1 | R37: 17.8 | S37: 17.5 | T37: 17.2 | U37: 16.6 | V37: 15.9 | W37: 15.3 | X37: 14.8 | Y37: 14.3 | Z37: 13.9 | AA37: 13.6 | AB37: Isol, хор | AC37: W/m2 | AD37: 50.1 | AE37: 81.2 | AF37: 109 | AG37: 149.7 | AH37: 97.2 | AI37: 58.3 | AJ37: 43.9
B38: φе | C38: % | D38: 78 | E38: 77 | F38: 79 | G38: 80 | H38: 81 | I38: 79 | J38: 76 | K38: 74 | L38: 71 | M38: 68 | N38: 65 | O38: 66 | P38: 67 | Q38: 68 | R38: 69 | S38: 69 | T38: 70 | U38: 73 | V38: 75 | W38: 78 | X38: 78 | Y38: 78 | Z38: 77 | AA38: 78 | AC38: темп | AD38: 1.9 | AE38: 2.7 | AF38: 5.1 | AG38: 10.2 | AH38: 13.8 | AI38: 9 | AJ38: 4.3
A39: Юни | B39: θе | C39: C | D39: 16 | E39: 16.8 | F39: 15.8 | G39: 15.3 | H39: 16.1 | I39: 15.9 | J39: 17.8 | K39: 19 | L39: 21.3 | M39: 22.5 | N39: 22.3 | O39: 23.8 | P39: 23.9 | Q39: 23.3 | R39: 24.1 | S39: 23.8 | T39: 22.3 | U39: 22.2 | V39: 20.9 | W39: 19.5 | X39: 17.8 | Y39: 17.6 | Z39: 17.4 | AA39: 16.4 | AB39: Летен период
B40: φе | C40: % | D40: 89 | E40: 89 | F40: 90 | G40: 91 | H40: 88 | I40: 89 | J40: 83 | K40: 79 | L40: 69 | M40: 65 | N40: 71 | O40: 59 | P40: 60 | Q40: 70 | R40: 59 | S40: 59 | T40: 73 | U40: 65 | V40: 72 | W40: 82 | X40: 86 | Y40: 87 | Z40: 89 | AA40: 88 | AB40: Isol, с | AC40: W/m2 | AD40: 77.7 | AE40: 84.3 | AF40: 83.7 | AG40: 75.9 | AH40: 60.7
A41: Юли | B41: θе | C41: C | D41: 18.8 | E41: 19.8 | F41: 18.5 | G41: 18.2 | H41: 19.2 | I41: 18.5 | J41: 20.5 | K41: 22 | L41: 24.1 | M41: 25.5 | N41: 25.9 | O41: 26.6 | P41: 26.8 | Q41: 26.5 | R41: 26.8 | S41: 26.5 | T41: 25.7 | U41: 25.1 | V41: 24 | W41: 22.9 | X41: 21.1 | Y41: 20.2 | Z41: 20.8 | AA41: 19.1 | AB41: Isol, и | AC41: W/m2 | AD41: 108.3 | AE41: 122 | AF41: 126.4 | AG41: 126.2 | AH41: 104.5
B42: φе | C42: % | D42: 87 | E42: 82 | F42: 89 | G42: 89 | H42: 83 | I42: 88 | J42: 81 | K42: 77 | L42: 68 | M42: 61 | N42: 65 | O42: 55 | P42: 56 | Q42: 65 | R42: 55 | S42: 57 | T42: 67 | U42: 62 | V42: 66 | W42: 74 | X42: 80 | Y42: 84 | Z42: 81 | AA42: 86 | AB42: Isol, ю | AC42: W/m2 | AD42: 90.5 | AE42: 97.4 | AF42: 104.9 | AG42: 126.5 | AH42: 133.7
A43: Август | B43: θе | C43: C | D43: 19.1 | E43: 18.8 | F43: 18.5 | G43: 18.3 | H43: 18 | I43: 18.7 | J43: 19.5 | K43: 20 | L43: 21.5 | M43: 22.9 | N43: 24.3 | O43: 24.6 | P43: 24.9 | Q43: 25.3 | R43: 25.1 | S43: 24.8 | T43: 24.5 | U43: 23.5 | V43: 22.5 | W43: 21.5 | X43: 20.9 | Y43: 20.3 | Z43: 19.8 | AA43: 19.5 | AB43: Isol, з | AC43: W/m2 | AD43: 108.3 | AE43: 122 | AF43: 126.4 | AG43: 126.2 | AH43: 104.5
B44: φе | C44: % | D44: 87 | E44: 87 | F44: 89 | G44: 89 | H44: 90 | I44: 89 | J44: 87 | K44: 85 | L44: 81 | M44: 77 | N44: 73 | O44: 72 | P44: 71 | Q44: 68 | R44: 70 | S44: 71 | T44: 72 | U44: 75 | V44: 78 | W44: 81 | X44: 83 | Y44: 85 | Z44: 86 | AA44: 87 | AB44: Isol, хор | AC44: W/m2 | AD44: 194.1 | AE44: 218 | AF44: 226.5 | AG44: 219.7 | AH44: 166.5
A45: Септември | B45: θе | C45: C | D45: 15.3 | E45: 15.5 | F45: 15.2 | G45: 14.7 | H45: 14.7 | I45: 14.6 | J45: 15.5 | K45: 16.7 | L45: 18.4 | M45: 20.1 | N45: 21.8 | O45: 22 | P45: 22.8 | Q45: 23.1 | R45: 22.7 | S45: 22.2 | T45: 21.3 | U45: 20.5 | V45: 19.2 | W45: 17.9 | X45: 17.3 | Y45: 16.5 | Z45: 16.5 | AA45: 15.7 | AD45: 15.6 | AE45: 20.2 | AF45: 23.7 | AG45: 22.3 | AH45: 19
B46: φе | C46: % | D46: 80 | E46: 79 | F46: 80 | G46: 81 | H46: 80 | I46: 80 | J46: 78 | K46: 73 | L46: 67 | M46: 61 | N46: 58 | O46: 56 | P46: 55 | Q46: 56 | R46: 55 | S46: 58 | T46: 63 | U46: 64 | V46: 68 | W46: 73 | X46: 74 | Y46: 78 | Z46: 77 | AA46: 79 | AE46: 1 | AF46: № на климатична зона
A47: Октомври | B47: θе | C47: C | D47: 11 | E47: 12 | F47: 11 | G47: 10 | H47: 12 | I47: 10 | J47: 10 | K47: 12 | L47: 13 | M47: 15 | N47: 16 | O47: 17 | P47: 18 | Q47: 18 | R47: 17 | S47: 17 | T47: 16 | U47: 14 | V47: 13 | W47: 14 | X47: 12 | Y47: 12 | Z47: 12 | AA47: 11 | AB47: DD | AE47: θе= | AF47: 1.9 | AG47: януари средна месечна
A48: Ноември | B48: θе | C48: C | D48: 6.1 | E48: 7 | F48: 6 | G48: 5.9 | H48: 6.8 | I48: 5.1 | J48: 4.9 | K48: 6.6 | L48: 7.2 | M48: 8.9 | N48: 10 | O48: 11 | P48: 12 | Q48: 12 | R48: 12 | S48: 11 | T48: 10 | U48: 8.7 | V48: 7.6 | W48: 7.9 | X48: 6.9 | Y48: 6.6 | Z48: 7.2 | AA48: 6.2 | AB48: 2400 | AE48: 21 | AF48: октомври
A49: Декември | B49: θе | C49: C | D49: 2.8 | E49: 2.7 | F49: 2.6 | G49: 2.6 | H49: 2.6 | I49: 2.6 | J49: 2.7 | K49: 2.6 | L49: 3.2 | M49: 3.7 | N49: 4.2 | O49: 4.8 | P49: 5.4 | Q49: 5.9 | R49: 5.5 | S49: 5 | T49: 4.5 | U49: 4.2 | V49: 4 | W49: 3.8 | X49: 3.6 | Y49: 3.3 | Z49: 3.1 | AA49: 2.9 | AE49: 20 | AF49: април
...

Sheet Как да ползваме
A2: Това е малка помощ за ползване на таблиците за изчисляване на енергийна ефективност на сгради направена като въпроси и отговори
A4: В: Как се попълва таблицата?
A5: О: Таблицата се попълва само между колонки от A до L като се попълват стойности в оранжевите клетки. Всички останали стойности се получават автоматично. Стойностите и данните след колонка L (от М нататък) са помощни при изчислението на отделните параметри.
A7: В: Защо ги няма всички формули?
A8: О: Разчита се на това че програмата се използва от лице запознато с Наредба №7 и е наясно кое как се получава. Същото важи и за проверяващите органи!
A10: В: Защо в разпечатката не се виждат температурите по месеци?
A11: О: Тъй като изчисленията се правят почасово за цялата година, таблицата става твърде обемиста и в разпечатката се представят само обобщени месечни резултати.
A13: В: Как да променя данните за климатичната зона за която ми трябва да направя изчисления?
A14: О: Просто трябва да въведете номер на климатична зона и всичко се въвежда автоматично.
A16: В: Мога ли да изтривам редове от таблицата?
A17: О: Можете. Таблицата не е защитена по никъкъв начин, но това най-вероятно ще доведе до грешни резултати.
A19: В: Как тогава да скрия неща които не искам да се разпечатват?
... A26: О: ДА! Желателно е да я разпространявате за да могат да се открият евентуални грешки по-бързо (ако повече хора гледат, по-бързо могат да хванат грешките). Програмата се разпространява под свободен лиценз GNU/GPL V2
V27: <<<<<
A28: В: Какво означава този лиценз GNU/GPL V2 ?
A29: О: На практика това означава че можете да разпространявате и променяте както и колкото си искате програмата но трябва да дадете възможност на тези на които я давате да правят същото, т.е. Да не поставят защити (съдържанието на лиценза можете да прочетете тук )
A30: http://bulgaria.sourceforge.net/prava/gplbg.html
A32: В: Кой всъщност е направил програмата и кого мога да питам относно попълването и алгоритъма?
A33: О: Програмата е разработена от инж. Милен Халков и активно тествана от инж. Стефан Маринов. За въпроси e-mail: milen_halkov@mail.bg
A35: В: Програмата много ми харесва и искам да даря на автора за да продължи разработката. Как може да стане това?
A36: О: Свържете се с автора на e-mail: milen_halkov@mail.bg
